<?xml version="1.0" ?>
<!-- This URDF is a conversion of our ModelJSON representation of a UR5 -->
<!-- See components/arm/universalrobots/ur5e.json for the original content -->
<robot name="ur5">

  <link name="base_link">
    <collision>
      <origin rpy="0.0 0.0 0.0" xyz="0.0 0.0 0.120"/>
      <geometry>
        <box size="0.151 0.151 0.240" />
      </geometry>
    </collision>
  </link> 

  <joint name="shoulder_pan_joint" type="revolute">
    <parent link="base_link"/>
    <child link="shoulder_link"/>
    <origin rpy="0.0 0.0 0.0" xyz="0.0 0.0 0.089159"/>
    <axis xyz="0 0 1"/>
    <limit effort="150.0" lower="-6.2831853" upper="6.2831853" velocity="3.14159265"/>
    <dynamics damping="0.0" friction="0.0"/>
  </joint>
  
  <link name="shoulder_link"/>

  <joint name="shoulder_lift_joint" type="revolute">
    <parent link="shoulder_link"/>
    <child link="upper_arm_link"/>
    <origin rpy="0.0 1.570796325 0.0" xyz="0.0 0.13585 0.0"/>
    <axis xyz="0 1 0"/>
    <limit effort="150.0" lower="-6.2831853" upper="6.2831853" velocity="3.14159265"/>
    <dynamics damping="0.0" friction="0.0"/>
  </joint>

  <link name="upper_arm_link">
    <collision>
      <origin rpy="0.0 0.0 0.0" xyz="0.0 0.0 0.225"/>
      <geometry>
        <box size="0.130 0.130 0.550" />
      </geometry>
    </collision>    
  </link>

  <joint name="elbow_joint" type="revolute">
    <parent link="upper_arm_link"/>
    <child link="forearm_link"/>
    <origin rpy="0.0 0.0 0.0" xyz="0.0 -0.1197 0.425"/>
    <axis xyz="0 1 0"/>
    <limit effort="150.0" lower="-6.2831853" upper="6.2831853" velocity="3.14159265"/>
    <dynamics damping="0.0" friction="0.0"/>
  </joint>

  <link name="forearm_link">
    <collision>
      <origin rpy="0.0 0.0 0.0" xyz="0.0 0.0 0.245"/>
      <geometry>
        <box size="0.100 0.100 0.490" />
      </geometry>
    </collision>    
  </link>

  <joint name="wrist_1_joint" type="revolute">
    <parent link="forearm_link"/>
    <child link="wrist_1_link"/>
    <origin rpy="0.0 1.570796325 0.0" xyz="0.0 0.0 0.39225"/>
    <axis xyz="0 1 0"/>
    <limit effort="28.0" lower="-3.14159265" upper="4.71" velocity="3.14159265"/>
    <dynamics damping="0.0" friction="0.0"/>
  </joint>

  <link name="wrist_1_link">
    <collision>
      <origin rpy="0.0 0.0 0.0" xyz="0.0 0.066 0.0"/>
      <geometry>
        <box size="0.080 0.20 0.080" />
      </geometry>
    </collision>    
  </link>

  <joint name="wrist_2_joint" type="revolute">
    <parent link="wrist_1_link"/>
    <child link="wrist_2_link"/>
    <origin rpy="0.0 0.0 0.0" xyz="0.0 0.093 0.0"/>
    <axis xyz="0 0 1"/>
    <limit effort="28.0" lower="-3.14159265" upper="4.71" velocity="3.14159265"/>
    <dynamics damping="0.0" friction="0.0"/>
  </joint>

  <link name="wrist_2_link">
    <collision>
      <origin rpy="0.0 0.0 0.0" xyz="0.0 0.0 0.1"/>
      <geometry>
        <box size="0.08 0.08 0.20" />
      </geometry>
    </collision>    
  </link>

  <joint name="wrist_3_joint" type="revolute">
    <parent link="wrist_2_link"/>
    <child link="wrist_3_link"/>
    <origin rpy="0.0 0.0 0.0" xyz="0.0 0.0 0.09465"/>
    <axis xyz="0 1 0"/>
    <limit effort="28.0" lower="-3.14159265" upper="3.14159265" velocity="3.14159265"/>
    <dynamics damping="0.0" friction="0.0"/>
  </joint>

  <link name="wrist_3_link">
    <collision>
      <origin rpy="0.0 0.0 0.0" xyz="0.0 0.1     0.0"/>
      <geometry>
        <box size="0.08 0.17 0.08" />
      </geometry>
    </collision>    
  </link>

  <joint name="ee_fixed_joint" type="revolute">
    <parent link="wrist_3_link"/>
    <child link="ee_link"/>
    <origin rpy="0.0 0.0 1.570796325" xyz="0.0 0.0823 0.0"/>
    <axis xyz="0 1 0"/>
    <limit effort="0.0" lower="0" upper="0" velocity="0"/>
  </joint>


  <link name="ee_link" />
  
  <link name="ee_link" />
</robot>