<?xml version="1.0" ?>
<robot name="UF_ROBOT">

  <link name="world"/>

  <link name="link_base">
    <origin rpy="0 0 0" xyz="-0.00025599 -2.8579E-06 0.085749"/>
    <collision>
      <geometry>
        <mesh filename="uf850meshes/link_base.stl"/>
      </geometry>
      <origin rpy="0 0 0" xyz="0 0 0"/>
    </collision>
  </link>

  <link name="link1">
    <origin rpy="0 0 0" xyz="5.7e-05 0.013842 -0.02055"/>
    <collision>
      <geometry>
        <mesh filename="uf850meshes/link1.stl"/>
      </geometry>
      <origin rpy="0 0 0" xyz="0 0 0"/>
    </collision>
  </link>

  <joint name="joint1" type="revolute">
    <parent link="link_base"/>
    <child link="link1"/>
    <origin rpy="0 0 0" xyz="0 0 0.364"/>
    <axis xyz="0 0 1"/>
    <limit lower="-6.283185307179586" upper="6.283185307179586"/>
  </joint>

  <link name="link2">
    <origin rpy="0 0 0" xyz="0.323425 9.5e-05 0.007586"/>
    <collision>
      <geometry>
        <mesh filename="uf850meshes/link2.stl"/>
      </geometry>
      <origin rpy="0 0 0" xyz="0 0 0"/>
    </collision>
  </link>

  <joint name="joint2" type="revolute">
    <parent link="link1"/>
    <child link="link2"/>
    <origin rpy="1.5708 -1.5708 0" xyz="0 0 0"/>
    <axis xyz="0 0 1"/>
    <limit lower="-2.3038346" upper="2.3038346"/>
  </joint>

  <link name="link3">
    <origin rpy="0 0 0" xyz="0.128834 0.11341 0.00978"/>
    <collision>
      <geometry>
        <mesh filename="uf850meshes/link3.stl"/>
      </geometry>
      <origin rpy="0 0 0" xyz="0 0 0"/>
    </collision>
  </link>

  <joint name="joint3" type="revolute">
    <parent link="link2"/>
    <child link="link3"/>
    <origin rpy="-3.1416 0 -1.5708" xyz="0.39 0 0"/>
    <axis xyz="0 0 1"/>
    <limit lower="-4.2236968" upper="0.061087"/>
  </joint>

  <link name="link4">
    <origin rpy="0 0 0" xyz="0.000266 -0.03833 -0.101915"/>
    <collision>
      <geometry>
        <mesh filename="uf850meshes/link4.stl"/>
      </geometry>
      <origin rpy="0 0 0" xyz="0 0 0"/>
    </collision>
  </link>

  <joint name="joint4" type="revolute">
    <parent link="link3"/>
    <child link="link4"/>
    <origin rpy="-1.5708 0 0" xyz="0.15 0.426 0"/>
    <axis xyz="0 0 1"/>
    <limit lower="-6.283185307179586" upper="6.283185307179586"/>
  </joint>

  <link name="link5">
    <origin rpy="0 0 0" xyz="5.7e-05 -0.015267 -0.001015"/>
    <collision>
      <geometry>
        <mesh filename="uf850meshes/link5.stl"/>
      </geometry>
      <origin rpy="0 0 0" xyz="0 0 0"/>
    </collision>
  </link>

  <joint name="joint5" type="revolute">
    <parent link="link4"/>
    <child link="link5"/>
    <origin rpy="-1.5708 0 0" xyz="0 0 0"/>
    <axis xyz="0 0 1"/>
    <limit lower="-2.1642" upper="2.1642" velocity="3.14"/>
  </joint>

  <link name="link6">
    <collision>
      <geometry>
        <mesh filename="uf850meshes/link6.stl"/>
      </geometry>
      <origin rpy="0 0 0" xyz="0 0 0"/>
    </collision>
  </link>

  <joint name="joint6" type="revolute">
    <parent link="link5"/>
    <child link="link6"/>
    <origin rpy="1.5708 0 0" xyz="0 -0.09 0"/>
    <axis xyz="0 0 1"/>
    <limit lower="-6.283185307179586" upper="6.283185307179586"/>
  </joint>

</robot>
